Workbook

Sheet Matriz Anexo VI
B1: MATRIZ DE ATENDIMENTO AO ANEXO VI DA INSTRUÇÃO NORMATIVA IAT Nº 37/2025
B2: Documento: | D2: Memorial de Caracterização do Empreendimento (MCE) – Sistema de Abastecimento de Água (SAA)
B3: Empreendimento: | D3: MCE do SAA da Sanepar de Candói/PR – Projeto nº 73349
B4: Empreendedor: | D4: Companhia de Saneamento do Paraná – Sanepar
B5: Referência normativa: | D5: IN IAT nº 37/2025, Anexo VI – Termo de Referência para Elaboração do MCE para SAA
B6: Modelo de referência: | D6: Anexo_VI_MCE_Palmeira; MCE Sanepar Palmeira SAA – 01; MCE Sanepar SAA Entre Rios – 00
B7: Situação da matriz: | D7: Rev. 00 – estrutura completa; avaliação item a item pendente do recebimento dos documentos-fonte do Projeto nº 73349
B9: Item do Anexo VI | C9: Informação exigida | D9: Item correspondente no MCE (estrutura modelo) | E9: Documento-fonte | F9: Informação encontrada? | G9: Situação | H9: Observação / Página-Item
B10: 0. EXIGÊNCIAS GERAIS DO ANEXO VI (preâmbulo)
B11: 0.1 | C11: MCE elaborado por técnico habilitado | D11: 6 Identificação da empresa responsável pelo documento | E11: - | F11: A verificar | G11: A VERIFICAR | H11: Anexo VI, preâmbulo: o MCE deve ser elaborado por técnico habilitado. Identificar empresa (VGBL Energy Ltda / Biocerne Ambiental, conforme MCEs modelo) e o(s) profissional(is) responsável(is), com registro no conselho de classe.
B12: 0.2 | C12: Anotação de Responsabilidade Técnica (ART) do MCE | D12: Anexos – ART's | E12: - | F12: A verificar | G12: A VERIFICAR | H12: Anexo VI, preâmbulo: o MCE deve ser apresentado acompanhado da respectiva ART. No MCE Palmeira consta 'ANEXO XI – ART's'; no MCE Entre Rios não há anexo de ART.
B13: I. INFORMAÇÕES CADASTRAIS
B14: I.1 | C14: Razão social | D14: 2 Identificação do Empreendimento | E14: [MCE-PAL] item 2; [MCE-ER] item 2 | F14: Sim | G14: DÚVIDA/VALIDAÇÃO NECESSÁRIA | H14: Dado institucional já adotado nos MCEs modelo: 'Companhia de Saneamento do Paraná – Sanepar'. Confirmar com a Sanepar para o Projeto nº 73349.
B15: I.2 | C15: Nome Fantasia | D15: 2 Identificação do Empreendimento | E15: - | F15: Não | G15: NÃO ATENDIDO | H15: Os MCEs modelo não trazem linha própria de 'Nome Fantasia' (a sigla aparece apenas na razão social). Incluir linha específica no MCE Candói (ex.: 'Sanepar'), após confirmação.
B16: I.3 | C16: CNPJ e Inscrição Estadual. Cadastro de Produtor Rural | D16: 2 Identificação do Empreendimento | E16: [MCE-PAL] item 2; [MCE-ER] item 2 | F16: Parcial | G16: DÚVIDA/VALIDAÇÃO NECESSÁRIA | H16: MCEs modelo: CNPJ 76.484.013/0001-45 e IE 101.800.80-64 (confirmar com a Sanepar). Cadastro de Produtor Rural: não se aplica ao empreendedor (pessoa jurídica de saneamento); registrar 'não se aplica' de forma justificada no MCE.
B17: I.4 | C17: Endereço completo da unidade a ser licenciada | D17: 2 Identificação do Empreendimento (com figuras de localização) | E17: - | F17: A verificar | G17: A VERIFICAR | H17: Seguir o padrão dos MCEs modelo: endereço da unidade principal (ETA) com rua, referência de cruzamento e figura; quando o sistema tiver unidades dispersas, informar e remeter ao item 3.3 (coordenadas). Depende do projeto do SAA Candói.
B18: I.5 | C18: Endereço para correspondência | D18: 2 Identificação do Empreendimento | E18: [MCE-PAL] item 2; [MCE-ER] item 2 | F18: Sim | G18: DÚVIDA/VALIDAÇÃO NECESSÁRIA | H18: MCEs modelo: Rua Engenheiros Rebouças nº 1376, Curitiba/PR, CEP 80215-900. Observação: o cabeçalho da IN 37 indica 'Rua Engenheiro Rebouças' para o IAT; conferir a grafia e o número do endereço da Sanepar.
B19: I.6 | C19: Nome do responsável, telefone | D19: 2 Identificação do Empreendimento – Quadro 1 (equipe Sanepar) | E19: - | F19: A verificar | G19: A VERIFICAR | H19: Quadro 1 dos MCEs modelo: Nome | Função/Vínculo | Registro profissional | Telefone. A equipe varia por projeto; obter a equipe Sanepar (GPOSD) do Projeto nº 73349 e definir quem figura como responsável perante o IAT.
B20: I.7 | C20: E-mail | D20: 2 Identificação do Empreendimento (nota do Quadro 1) | E20: - | F20: A verificar | G20: A VERIFICAR | H20: No MCE Entre Rios o e-mail aparece apenas como nota de rodapé do Quadro 1; no MCE Palmeira não consta. Informar e-mail do responsável de forma explícita no MCE Candói.
B21: II. CARACTERIZAÇÃO DA ÁREA
B22: II.1 | C22: Área onde será implantada a atividade (área total, área construída e área livre) | D22: 3.2 Área onde será implantada a atividade (Quadros 2 e 3) | E22: - | F22: A verificar | G22: A VERIFICAR | H22: A IN pede três valores (total, construída e livre). Os MCEs modelo informam apenas a área ocupada por unidade, sem discriminar construída/livre: incluir essas colunas no Quadro 2 do MCE Candói. Quadro 3: extensão e material das adutoras.
B23: II.2 | C23: Coordenadas Geográficas e UTM | D23: 3.3 Coordenadas Geográficas e UTM | E23: - | F23: A verificar | G23: A VERIFICAR | H23: Apresentar as duas formas (geográficas em graus e UTM), com datum SIRGAS 2000 e fuso. Os MCEs modelo trazem só UTM: incluir também as coordenadas geográficas. Abranger captação, elevatórias, travessias, ETA, reservatórios e demais unidades.
B24: II.3 | C24: Tipo e característica do solo | D24: 3.5.1 Pedologia; 3.5.1.1 Uso do Solo | E24: - | F24: A verificar | G24: A VERIFICAR | H24: Padrão dos modelos: classes de solo da região (EMBRAPA/SiBCS), descrição de cada classe, mapa de solos da área e fotos/perfis. Para Candói, identificar as classes no mapa de solos do PR.
B25: II.4 | C25: Topografia | D25: 3.5.2 Geomorfologia (mapa geomorfológico, relevo, altimetria, declividade) | E25: - | F25: A verificar | G25: A VERIFICAR | H25: Padrão dos modelos: compartimento geomorfológico (MINEROPAR/UFPR, 2006), subunidade morfoescultural, altitudes, grau de dissecação, figuras de geomorfologia, altimetria e declividade.
B26: II.5 | C26: Recursos Hídricos (nascentes, olhos d'água, cursos d'água, etc.) | D26: 3.5.3 Hidrologia | E26: - | F26: A verificar | G26: A VERIFICAR | H26: Bacia hidrográfica (Resolução CERH/PR nº 49/2006), manancial, classe de enquadramento, área de drenagem no ponto de captação e cursos d'água interceptados (travessias). Os modelos não tratam de nascentes/olhos d'água: declarar presença ou ausência na área.
B27: II.6 | C27: Geologia / hidrogeologia / geotecnia | D27: 3.5.4 Geologia; 3.5.5 Hidrogeologia | E27: - | F27: A verificar | G27: A VERIFICAR | H27: Geologia e hidrogeologia seguem o padrão dos modelos (Bacia do Paraná, aquíferos, poços/BACE Sanepar). Geotecnia não é tratada nos MCEs modelo: incluir (sondagens SPT/trado, se houver no projeto 73349).
B28: II.7 | C28: Cobertura Vegetal | D28: 3.6 Caracterização Meio Biótico (Cobertura Vegetal) | E28: - | F28: A verificar | G28: A VERIFICAR | H28: Enquadramento fitogeográfico (IAT, 2023; IBGE, 2012), aspectos da vegetação na área, espécies registradas e remissão ao Inventário Florestal quando houver supressão.
B29: II.8 | C29: Acessos (alternativas, condições de tráfego) | D29: 3.4 Alternativa de Acessos ao Empreendimento | E29: - | F29: A verificar | G29: A VERIFICAR | H29: Do estado ao município (rodovias, distâncias de Curitiba) e do município às unidades (alternativas viárias, pavimentação, estradas rurais), com condições de tráfego e obras viárias em andamento.
B30: II.9 | C30: Características do entorno (uso do solo, residências, áreas de interesse ambiental, etc.) | D30: 3.5.1.1 Uso do Solo; 3.6.1 APP e Reserva Legal; 3.7 Meio Socioeconômico (3.7.1 Residências, condições do entorno) | E30: - | F30: A verificar | G30: A VERIFICAR | H30: Uso do solo ao longo do traçado, residências, escolas, igrejas e comércios próximos (registro fotográfico), atrativos culturais/turísticos e áreas de interesse ambiental (APP, RL, UC).
B31: III. CROQUI DE LOCALIZAÇÃO DO EMPREENDIMENTO COM IMAGEM AÉREA E CONTENDO NO MÍNIMO:
B32: III.0 | C32: Croqui elaborado sobre imagem aérea | D32: Anexos – Croqui / Mapa temático do sistema projetado; figuras do item 3.3 | E32: - | F32: A verificar | G32: A VERIFICAR | H32: Requisito do título da Seção III ('com imagem aérea'), omitido na matriz Palmeira. Verificar se o croqui do MCE Candói tem imagem aérea/de satélite ao fundo.
B33: III.1 | C33: Implantação da Estação de Tratamento de Água | D33: Anexos – Croqui; item 3.3 | E33: - | F33: A verificar | G33: A VERIFICAR | H33: Representar a implantação da ETA no croqui.
B34: III.2 | C34: Manancial de abastecimento | D34: Anexos – Croqui; item 3.3 | E34: - | F34: A verificar | G34: A VERIFICAR | H34: Representar o manancial e o ponto de captação.
B35: III.3 | C35: Sistema de adução e captação desde o manancial até a ETA | D35: Anexos – Croqui; item 3.3 | E35: - | F35: A verificar | G35: A VERIFICAR | H35: Captação, elevatórias, pré-sedimentador (se houver) e traçado das adutoras de água bruta até a ETA.
B36: III.4 | C36: Sistema de armazenamento e distribuição | D36: Anexos – Croqui; item 3.3 | E36: - | F36: A verificar | G36: A VERIFICAR | H36: Reservatórios, elevatórias de água tratada, adutoras de água tratada e rede de distribuição.
B37: III.5 | C37: Delimitação de imóveis de terceiros afetados (com indicação do número da matrícula) | D37: Anexos – Croqui; item 4.2 (desapropriação) | E37: - | F37: A verificar | G37: A VERIFICAR | H37: Não atendido nos MCEs modelo (sem números de matrícula). Obter matrículas dos imóveis a desapropriar/servidão junto à Sanepar.
B38: III.6 | C38: Cursos hídricos | D38: Anexos – Croqui; item 3.5.3 | E38: - | F38: A verificar | G38: A VERIFICAR | H38: Representar os cursos hídricos e os pontos de travessia.
B39: III.7 | C39: Cobertura florestal das áreas afetadas | D39: Anexos – Croqui; item 3.6 | E39: - | F39: A verificar | G39: A VERIFICAR | H39: Representar a vegetação nas áreas de intervenção (base: Inventário Florestal, se houver).
B40: III.8 | C40: Áreas de Preservação Permanente | D40: Anexos – Croqui; item 3.6.1 | E40: - | F40: A verificar | G40: A VERIFICAR | H40: Delimitar APP (Lei nº 12.651/2012 e CAR/SICAR).
B41: III.9 | C41: Reserva legal e demais áreas relevantes | D41: Anexos – Croqui; item 3.6.1 | E41: - | F41: A verificar | G41: A VERIFICAR | H41: Delimitar Reserva Legal (CAR/SICAR) e demais áreas relevantes (UC, zona de amortecimento, áreas de manancial etc.).
...

Sheet Resumo
B1: RESUMO DE ATENDIMENTO – MCE do SAA Sanepar Candói – Projeto nº 73349
B3: Grupo | C3: Total | D3: ATENDIDO | E3: PARCIALMENTE ATENDIDO | F3: NÃO ATENDIDO | G3: DÚVIDA/VALIDAÇÃO NECESSÁRIA | H3: NÃO SE APLICA | I3: A VERIFICAR
B4: 0. Exigências gerais | C4: =COUNTIFS('Matriz Anexo VI'!$B$10:$B$72,"0.*",'Matriz Anexo VI'!$G$10:$G$72,"?*") | D4: =COUNTIFS('Matriz Anexo VI'!$B$10:$B$72,"0.*",'Matriz Anexo VI'!$G$10:$G$72,"ATENDIDO") | E4: =COUNTIFS('Matriz Anexo VI'!$B$10:$B$72,"0.*",'Matriz Anexo VI'!$G$10:$G$72,"PARCIALMENTE ATENDIDO") | F4: =COUNTIFS('Matriz Anexo VI'!$B$10:$B$72,"0.*",'Matriz Anexo VI'!$G$10:$G$72,"NÃO ATENDIDO") | G4: =COUNTIFS('Matriz Anexo VI'!$B$10:$B$72,"0.*",'Matriz Anexo VI'!$G$10:$G$72,"DÚVIDA/VALIDAÇÃO NECESSÁRIA") | H4: =COUNTIFS('Matriz Anexo VI'!$B$10:$B$72,"0.*",'Matriz Anexo VI'!$G$10:$G$72,"NÃO SE APLICA") | I4: =COUNTIFS('Matriz Anexo VI'!$B$10:$B$72,"0.*",'Matriz Anexo VI'!$G$10:$G$72,"A VERIFICAR")
B5: I. Informações cadastrais | C5: =COUNTIFS('Matriz Anexo VI'!$B$10:$B$72,"I.*",'Matriz Anexo VI'!$G$10:$G$72,"?*") | D5: =COUNTIFS('Matriz Anexo VI'!$B$10:$B$72,"I.*",'Matriz Anexo VI'!$G$10:$G$72,"ATENDIDO") | E5: =COUNTIFS('Matriz Anexo VI'!$B$10:$B$72,"I.*",'Matriz Anexo VI'!$G$10:$G$72,"PARCIALMENTE ATENDIDO") | F5: =COUNTIFS('Matriz Anexo VI'!$B$10:$B$72,"I.*",'Matriz Anexo VI'!$G$10:$G$72,"NÃO ATENDIDO") | G5: =COUNTIFS('Matriz Anexo VI'!$B$10:$B$72,"I.*",'Matriz Anexo VI'!$G$10:$G$72,"DÚVIDA/VALIDAÇÃO NECESSÁRIA") | H5: =COUNTIFS('Matriz Anexo VI'!$B$10:$B$72,"I.*",'Matriz Anexo VI'!$G$10:$G$72,"NÃO SE APLICA") | I5: =COUNTIFS('Matriz Anexo VI'!$B$10:$B$72,"I.*",'Matriz Anexo VI'!$G$10:$G$72,"A VERIFICAR")
B6: II. Caracterização da área | C6: =COUNTIFS('Matriz Anexo VI'!$B$10:$B$72,"II.*",'Matriz Anexo VI'!$G$10:$G$72,"?*") | D6: =COUNTIFS('Matriz Anexo VI'!$B$10:$B$72,"II.*",'Matriz Anexo VI'!$G$10:$G$72,"ATENDIDO") | E6: =COUNTIFS('Matriz Anexo VI'!$B$10:$B$72,"II.*",'Matriz Anexo VI'!$G$10:$G$72,"PARCIALMENTE ATENDIDO") | F6: =COUNTIFS('Matriz Anexo VI'!$B$10:$B$72,"II.*",'Matriz Anexo VI'!$G$10:$G$72,"NÃO ATENDIDO") | G6: =COUNTIFS('Matriz Anexo VI'!$B$10:$B$72,"II.*",'Matriz Anexo VI'!$G$10:$G$72,"DÚVIDA/VALIDAÇÃO NECESSÁRIA") | H6: =COUNTIFS('Matriz Anexo VI'!$B$10:$B$72,"II.*",'Matriz Anexo VI'!$G$10:$G$72,"NÃO SE APLICA") | I6: =COUNTIFS('Matriz Anexo VI'!$B$10:$B$72,"II.*",'Matriz Anexo VI'!$G$10:$G$72,"A VERIFICAR")
B7: III. Croqui de localização | C7: =COUNTIFS('Matriz Anexo VI'!$B$10:$B$72,"III.*",'Matriz Anexo VI'!$G$10:$G$72,"?*") | D7: =COUNTIFS('Matriz Anexo VI'!$B$10:$B$72,"III.*",'Matriz Anexo VI'!$G$10:$G$72,"ATENDIDO") | E7: =COUNTIFS('Matriz Anexo VI'!$B$10:$B$72,"III.*",'Matriz Anexo VI'!$G$10:$G$72,"PARCIALMENTE ATENDIDO") | F7: =COUNTIFS('Matriz Anexo VI'!$B$10:$B$72,"III.*",'Matriz Anexo VI'!$G$10:$G$72,"NÃO ATENDIDO") | G7: =COUNTIFS('Matriz Anexo VI'!$B$10:$B$72,"III.*",'Matriz Anexo VI'!$G$10:$G$72,"DÚVIDA/VALIDAÇÃO NECESSÁRIA") | H7: =COUNTIFS('Matriz Anexo VI'!$B$10:$B$72,"III.*",'Matriz Anexo VI'!$G$10:$G$72,"NÃO SE APLICA") | I7: =COUNTIFS('Matriz Anexo VI'!$B$10:$B$72,"III.*",'Matriz Anexo VI'!$G$10:$G$72,"A VERIFICAR")
B8: IV. Caracterização do empreendimento | C8: =COUNTIFS('Matriz Anexo VI'!$B$10:$B$72,"IV.*",'Matriz Anexo VI'!$G$10:$G$72,"?*") | D8: =COUNTIFS('Matriz Anexo VI'!$B$10:$B$72,"IV.*",'Matriz Anexo VI'!$G$10:$G$72,"ATENDIDO") | E8: =COUNTIFS('Matriz Anexo VI'!$B$10:$B$72,"IV.*",'Matriz Anexo VI'!$G$10:$G$72,"PARCIALMENTE ATENDIDO") | F8: =COUNTIFS('Matriz Anexo VI'!$B$10:$B$72,"IV.*",'Matriz Anexo VI'!$G$10:$G$72,"NÃO ATENDIDO") | G8: =COUNTIFS('Matriz Anexo VI'!$B$10:$B$72,"IV.*",'Matriz Anexo VI'!$G$10:$G$72,"DÚVIDA/VALIDAÇÃO NECESSÁRIA") | H8: =COUNTIFS('Matriz Anexo VI'!$B$10:$B$72,"IV.*",'Matriz Anexo VI'!$G$10:$G$72,"NÃO SE APLICA") | I8: =COUNTIFS('Matriz Anexo VI'!$B$10:$B$72,"IV.*",'Matriz Anexo VI'!$G$10:$G$72,"A VERIFICAR")
B9: V. Complementares IN 37 | C9: =COUNTIFS('Matriz Anexo VI'!$B$10:$B$72,"V.*",'Matriz Anexo VI'!$G$10:$G$72,"?*") | D9: =COUNTIFS('Matriz Anexo VI'!$B$10:$B$72,"V.*",'Matriz Anexo VI'!$G$10:$G$72,"ATENDIDO") | E9: =COUNTIFS('Matriz Anexo VI'!$B$10:$B$72,"V.*",'Matriz Anexo VI'!$G$10:$G$72,"PARCIALMENTE ATENDIDO") | F9: =COUNTIFS('Matriz Anexo VI'!$B$10:$B$72,"V.*",'Matriz Anexo VI'!$G$10:$G$72,"NÃO ATENDIDO") | G9: =COUNTIFS('Matriz Anexo VI'!$B$10:$B$72,"V.*",'Matriz Anexo VI'!$G$10:$G$72,"DÚVIDA/VALIDAÇÃO NECESSÁRIA") | H9: =COUNTIFS('Matriz Anexo VI'!$B$10:$B$72,"V.*",'Matriz Anexo VI'!$G$10:$G$72,"NÃO SE APLICA") | I9: =COUNTIFS('Matriz Anexo VI'!$B$10:$B$72,"V.*",'Matriz Anexo VI'!$G$10:$G$72,"A VERIFICAR")
B10: TOTAL GERAL (0 a IV = Anexo VI) | C10: =SUM(C4:C8) | D10: =SUM(D4:D8) | E10: =SUM(E4:E8) | F10: =SUM(F4:F8) | G10: =SUM(G4:G8) | H10: =SUM(H4:H8) | I10: =SUM(I4:I8)
B11: TOTAL GERAL (0 a V) | C11: =SUM(C4:C9) | D11: =SUM(D4:D9) | E11: =SUM(E4:E9) | F11: =SUM(F4:F9) | G11: =SUM(G4:G9) | H11: =SUM(H4:H9) | I11: =SUM(I4:I9)

Sheet Legenda
A1: LEGENDA - CLASSIFICAÇÃO DE SITUAÇÃO
A3: ATENDIDO | B3: Informação encontrada nos documentos fornecidos e suficientemente clara.
A4: PARCIALMENTE ATENDIDO | B4: Existe informação nos documentos, porém incompleta ou faltam dados complementares.
A5: NÃO ATENDIDO | B5: Informação não localizada em nenhum dos documentos fornecidos.
A6: DÚVIDA/VALIDAÇÃO NECESSÁRIA | B6: Existem informações conflitantes, ambíguas, com nomenclatura/rotulagem tecnicamente inadequada, ou que necessitam confirmação do cliente/projetista antes de uso no MCE.
A7: NÃO SE APLICA | B7: Exigência que não se aplica ao empreendimento, com justificativa registrada na coluna Observação.
A8: A VERIFICAR | B8: Item ainda não avaliado: aguardando os documentos-fonte do Projeto nº 73349 (projeto básico, memorial descritivo e estudos ambientais).
A10: Documentos-fonte (siglas utilizadas na matriz):
A11: [IN37] = Instrução Normativa IAT nº 37, de 28 de abril de 2025 (republicada) – licenciamento ambiental de SES e SAA no Paraná
A12: [IN37-VI] = Instrução Normativa IAT nº 37/2025, Anexo VI – Termo de Referência para Elaboração do MCE para SAA
A13: [MCE-PAL] = Memorial de Caracterização do Empreendimento – Sanepar Palmeira SAA – 01 (modelo de referência)
A14: [MCE-ER] = Memorial de Caracterização do Empreendimento – Sanepar SAA Entre Rios – 00 (modelo de referência)
A15: [MATRIZ-PAL] = Anexo_VI_MCE_Palmeira (modelo de referência desta matriz)
A16: [PROJ-73349] = Projeto Básico / Memorial Descritivo do SAA Sanepar Candói – Projeto nº 73349 (a fornecer)
A17: [MEM-73349] = Memorial Descritivo dos Estudos Ambientais do SAA Candói – Projeto nº 73349 (a fornecer)
A18: [INV-FLOR] = Inventário Florestal / Relatório de caracterização da flora do Projeto nº 73349 (a fornecer, se houver supressão)
A20: Notas de uso:
A21: 1. Os itens 0 a IV reproduzem integralmente o Anexo VI da IN 37/2025, na mesma ordem e redação; o item IV.9 repete o IV.2 no próprio texto normativo e foi mantido.
A22: 2. O grupo V reúne exigências da IN 37 fora do Anexo VI que têm reflexo no conteúdo do MCE ou no protocolo do licenciamento.
... A24: 4. As colunas 'Informação encontrada?' e 'Situação' têm listas suspensas; a cor da Situação é atualizada automaticamente e a aba Resumo é recalculada.
